Logged in as
Sentinel
570414326943580191
---------------
Ignoring exception in command None:
discord.ext.commands.errors.CommandNotFound: Command "PC" is not found
Ignoring exception in command None:
discord.ext.commands.errors.CommandNotFound: Command "GG" is not found
Logged in as
Sentinel
570414326943580191
---------------
Logged in as
Sentinel
570414326943580191
---------------
Logged in as
Sentinel
570414326943580191
---------------
Logged in as
Sentinel
570414326943580191
---------------
Logged in as
Sentinel
570414326943580191
---------------
Logged in as
Sentinel
570414326943580191
---------------
Logged in as
Sentinel
570414326943580191
---------------
Logged in as
Sentinel
570414326943580191
---------------
Task exception was never retrieved
future: <Task finished coro=<status_task() done, defined at Sentinel.py:33> exception=ConnectionClosed('WebSocket connection is closed: code = 1006 (connection closed abnormally [internal]), no reason',)>
Traceback (most recent call last):
  File "/home/zach/.local/lib/python3.6/site-packages/websockets/protocol.py", line 528, in transfer_data
    msg = yield from self.read_message()
  File "/home/zach/.local/lib/python3.6/site-packages/websockets/protocol.py", line 580, in read_message
    frame = yield from self.read_data_frame(max_size=self.max_size)
  File "/home/zach/.local/lib/python3.6/site-packages/websockets/protocol.py", line 645, in read_data_frame
    frame = yield from self.read_frame(max_size)
  File "/home/zach/.local/lib/python3.6/site-packages/websockets/protocol.py", line 710, in read_frame
    extensions=self.extensions,
  File "/home/zach/.local/lib/python3.6/site-packages/websockets/framing.py", line 100, in read
    data = yield from reader(2)
  File "/usr/lib/python3.6/asyncio/streams.py", line 672, in readexactly
    raise IncompleteReadError(incomplete, n)
asyncio.streams.IncompleteReadError: 0 bytes read on a total of 2 expected bytes

The above exception was the direct cause of the following exception:

Traceback (most recent call last):
  File "Sentinel.py", line 41, in status_task
    await bot.change_presence(activity=Game(name=new_status))
  File "/home/zach/.local/lib/python3.6/site-packages/discord/client.py", line 842, in change_presence
    await self.ws.change_presence(activity=activity, status=status, afk=afk)
  File "/home/zach/.local/lib/python3.6/site-packages/discord/gateway.py", line 506, in change_presence
    await self.send(sent)
  File "/home/zach/.local/lib/python3.6/site-packages/discord/gateway.py", line 476, in send
    await super().send(data)
  File "/home/zach/.local/lib/python3.6/site-packages/websockets/protocol.py", line 361, in send
    yield from self.ensure_open()
  File "/home/zach/.local/lib/python3.6/site-packages/websockets/protocol.py", line 501, in ensure_open
    self.close_code, self.close_reason) from self.transfer_data_exc
websockets.exceptions.ConnectionClosed: WebSocket connection is closed: code = 1006 (connection closed abnormally [internal]), no reason
Task exception was never retrieved
future: <Task finished coro=<status_task() done, defined at Sentinel.py:33> exception=ConnectionClosed('WebSocket connection is closed: code = 1006 (connection closed abnormally [internal]), no reason',)>
Traceback (most recent call last):
  File "/home/zach/.local/lib/python3.6/site-packages/websockets/protocol.py", line 528, in transfer_data
    msg = yield from self.read_message()
  File "/home/zach/.local/lib/python3.6/site-packages/websockets/protocol.py", line 580, in read_message
    frame = yield from self.read_data_frame(max_size=self.max_size)
  File "/home/zach/.local/lib/python3.6/site-packages/websockets/protocol.py", line 645, in read_data_frame
    frame = yield from self.read_frame(max_size)
  File "/home/zach/.local/lib/python3.6/site-packages/websockets/protocol.py", line 710, in read_frame
    extensions=self.extensions,
  File "/home/zach/.local/lib/python3.6/site-packages/websockets/framing.py", line 100, in read
    data = yield from reader(2)
  File "/usr/lib/python3.6/asyncio/streams.py", line 672, in readexactly
    raise IncompleteReadError(incomplete, n)
asyncio.streams.IncompleteReadError: 0 bytes read on a total of 2 expected bytes

The above exception was the direct cause of the following exception:

Traceback (most recent call last):
  File "Sentinel.py", line 41, in status_task
    await bot.change_presence(activity=Game(name=new_status))
  File "/home/zach/.local/lib/python3.6/site-packages/discord/client.py", line 842, in change_presence
    await self.ws.change_presence(activity=activity, status=status, afk=afk)
  File "/home/zach/.local/lib/python3.6/site-packages/discord/gateway.py", line 506, in change_presence
    await self.send(sent)
  File "/home/zach/.local/lib/python3.6/site-packages/discord/gateway.py", line 476, in send
    await super().send(data)
  File "/home/zach/.local/lib/python3.6/site-packages/websockets/protocol.py", line 361, in send
    yield from self.ensure_open()
  File "/home/zach/.local/lib/python3.6/site-packages/websockets/protocol.py", line 501, in ensure_open
    self.close_code, self.close_reason) from self.transfer_data_exc
websockets.exceptions.ConnectionClosed: WebSocket connection is closed: code = 1006 (connection closed abnormally [internal]), no reason
Logged in as
Sentinel
570414326943580191
---------------
Task exception was never retrieved
future: <Task finished coro=<status_task() done, defined at Sentinel.py:33> exception=ConnectionClosed('WebSocket connection is closed: code = 1006 (connection closed abnormally [internal]), no reason',)>
Traceback (most recent call last):
  File "/home/zach/.local/lib/python3.6/site-packages/websockets/protocol.py", line 528, in transfer_data
    msg = yield from self.read_message()
  File "/home/zach/.local/lib/python3.6/site-packages/websockets/protocol.py", line 580, in read_message
    frame = yield from self.read_data_frame(max_size=self.max_size)
  File "/home/zach/.local/lib/python3.6/site-packages/websockets/protocol.py", line 645, in read_data_frame
    frame = yield from self.read_frame(max_size)
  File "/home/zach/.local/lib/python3.6/site-packages/websockets/protocol.py", line 710, in read_frame
    extensions=self.extensions,
  File "/home/zach/.local/lib/python3.6/site-packages/websockets/framing.py", line 100, in read
    data = yield from reader(2)
  File "/usr/lib/python3.6/asyncio/streams.py", line 672, in readexactly
    raise IncompleteReadError(incomplete, n)
asyncio.streams.IncompleteReadError: 0 bytes read on a total of 2 expected bytes

The above exception was the direct cause of the following exception:

Traceback (most recent call last):
  File "Sentinel.py", line 41, in status_task
    await bot.change_presence(activity=Game(name=new_status))
  File "/home/zach/.local/lib/python3.6/site-packages/discord/client.py", line 842, in change_presence
    await self.ws.change_presence(activity=activity, status=status, afk=afk)
  File "/home/zach/.local/lib/python3.6/site-packages/discord/gateway.py", line 506, in change_presence
    await self.send(sent)
  File "/home/zach/.local/lib/python3.6/site-packages/discord/gateway.py", line 476, in send
    await super().send(data)
  File "/home/zach/.local/lib/python3.6/site-packages/websockets/protocol.py", line 361, in send
    yield from self.ensure_open()
  File "/home/zach/.local/lib/python3.6/site-packages/websockets/protocol.py", line 501, in ensure_open
    self.close_code, self.close_reason) from self.transfer_data_exc
websockets.exceptions.ConnectionClosed: WebSocket connection is closed: code = 1006 (connection closed abnormally [internal]), no reason
Logged in as
Sentinel
570414326943580191
---------------
Task exception was never retrieved
future: <Task finished coro=<status_task() done, defined at Sentinel.py:33> exception=ConnectionClosed('WebSocket connection is closed: code = 1006 (connection closed abnormally [internal]), no reason',)>
Traceback (most recent call last):
  File "/home/zach/.local/lib/python3.6/site-packages/websockets/protocol.py", line 528, in transfer_data
    msg = yield from self.read_message()
  File "/home/zach/.local/lib/python3.6/site-packages/websockets/protocol.py", line 580, in read_message
    frame = yield from self.read_data_frame(max_size=self.max_size)
  File "/home/zach/.local/lib/python3.6/site-packages/websockets/protocol.py", line 645, in read_data_frame
    frame = yield from self.read_frame(max_size)
  File "/home/zach/.local/lib/python3.6/site-packages/websockets/protocol.py", line 710, in read_frame
    extensions=self.extensions,
  File "/home/zach/.local/lib/python3.6/site-packages/websockets/framing.py", line 100, in read
    data = yield from reader(2)
  File "/usr/lib/python3.6/asyncio/streams.py", line 672, in readexactly
    raise IncompleteReadError(incomplete, n)
asyncio.streams.IncompleteReadError: 0 bytes read on a total of 2 expected bytes

The above exception was the direct cause of the following exception:

Traceback (most recent call last):
  File "Sentinel.py", line 41, in status_task
    await bot.change_presence(activity=Game(name=new_status))
  File "/home/zach/.local/lib/python3.6/site-packages/discord/client.py", line 842, in change_presence
    await self.ws.change_presence(activity=activity, status=status, afk=afk)
  File "/home/zach/.local/lib/python3.6/site-packages/discord/gateway.py", line 506, in change_presence
    await self.send(sent)
  File "/home/zach/.local/lib/python3.6/site-packages/discord/gateway.py", line 476, in send
    await super().send(data)
  File "/home/zach/.local/lib/python3.6/site-packages/websockets/protocol.py", line 361, in send
    yield from self.ensure_open()
  File "/home/zach/.local/lib/python3.6/site-packages/websockets/protocol.py", line 501, in ensure_open
    self.close_code, self.close_reason) from self.transfer_data_exc
websockets.exceptions.ConnectionClosed: WebSocket connection is closed: code = 1006 (connection closed abnormally [internal]), no reason
Logged in as
Sentinel
570414326943580191
---------------
Logged in as
Sentinel
570414326943580191
---------------
Logged in as
Sentinel
570414326943580191
---------------
Logged in as
Sentinel
570414326943580191
---------------
Logged in as
Sentinel
570414326943580191
---------------
Ignoring exception in command None:
discord.ext.commands.errors.CommandNotFound: Command "framedata" is not found
Logged in as
Sentinel
570414326943580191
---------------
Logged in as
Sentinel
570414326943580191
---------------
Logged in as
Sentinel
570414326943580191
---------------
